[2023-11-30T16:01:59.503+0800] {taskinstance.py:1159} INFO - Dependencies all met for dep_context=non-requeueable deps ti=<TaskInstance: fantasy_premier_league_second_debug.get_list_folder manual__2023-11-30T08:01:56.953260+00:00 [queued]>
[2023-11-30T16:01:59.513+0800] {taskinstance.py:1159} INFO - Dependencies all met for dep_context=requeueable deps ti=<TaskInstance: fantasy_premier_league_second_debug.get_list_folder manual__2023-11-30T08:01:56.953260+00:00 [queued]>
[2023-11-30T16:01:59.513+0800] {taskinstance.py:1361} INFO - Starting attempt 1 of 1
[2023-11-30T16:01:59.539+0800] {taskinstance.py:1382} INFO - Executing <Task(PythonOperator): get_list_folder> on 2023-11-30 08:01:56.953260+00:00
[2023-11-30T16:01:59.543+0800] {standard_task_runner.py:57} INFO - Started process 38362 to run task
[2023-11-30T16:01:59.558+0800] {standard_task_runner.py:84} INFO - Running: ['airflow', 'tasks', 'run', 'fantasy_premier_league_second_debug', 'get_list_folder', 'manual__2023-11-30T08:01:56.953260+00:00', '--job-id', '72', '--raw', '--subdir', 'DAGS_FOLDER/azfar_second_dag.py', '--cfg-path', '/tmp/tmpiib9zphc']
[2023-11-30T16:01:59.559+0800] {standard_task_runner.py:85} INFO - Job 72: Subtask get_list_folder
[2023-11-30T16:01:59.652+0800] {task_command.py:416} INFO - Running <TaskInstance: fantasy_premier_league_second_debug.get_list_folder manual__2023-11-30T08:01:56.953260+00:00 [running]> on host azfartitu.
[2023-11-30T16:01:59.762+0800] {taskinstance.py:1662} INFO - Exporting env vars: AIRFLOW_CTX_DAG_OWNER='airflow' AIRFLOW_CTX_DAG_ID='fantasy_premier_league_second_debug' AIRFLOW_CTX_TASK_ID='get_list_folder' AIRFLOW_CTX_EXECUTION_DATE='2023-11-30T08:01:56.953260+00:00' AIRFLOW_CTX_TRY_NUMBER='1' AIRFLOW_CTX_DAG_RUN_ID='manual__2023-11-30T08:01:56.953260+00:00'
[2023-11-30T16:01:59.763+0800] {taskinstance.py:1937} ERROR - Task failed with exception
Traceback (most recent call last):
  File "/home/azfarmustafa/airflow_tutorial/.venv/lib/python3.10/site-packages/airflow/operators/python.py", line 192, in execute
    return_value = self.execute_callable()
  File "/home/azfarmustafa/airflow_tutorial/.venv/lib/python3.10/site-packages/airflow/operators/python.py", line 209, in execute_callable
    return self.python_callable(*self.op_args, **self.op_kwargs)
  File "/home/azfarmustafa/airflow_tutorial/dags/azfar_second_dag.py", line 40, in get_list_folder
    list_of_files = az_hook.get_blobs_list(container_name=container_name)
AttributeError: 'AzureDataLakeStorageV2Hook' object has no attribute 'get_blobs_list'
[2023-11-30T16:01:59.777+0800] {taskinstance.py:1400} INFO - Marking task as FAILED. dag_id=fantasy_premier_league_second_debug, task_id=get_list_folder, execution_date=20231130T080156, start_date=20231130T080159, end_date=20231130T080159
[2023-11-30T16:01:59.797+0800] {standard_task_runner.py:104} ERROR - Failed to execute job 72 for task get_list_folder ('AzureDataLakeStorageV2Hook' object has no attribute 'get_blobs_list'; 38362)
[2023-11-30T16:01:59.811+0800] {local_task_job_runner.py:228} INFO - Task exited with return code 1
[2023-11-30T16:01:59.825+0800] {taskinstance.py:2778} INFO - 0 downstream tasks scheduled from follow-on schedule check
