[2023-11-30T23:19:05.012+0800] {taskinstance.py:1159} INFO - Dependencies all met for dep_context=non-requeueable deps ti=<TaskInstance: fantasy_premier_league_second_debug.get_old_date manual__2023-11-30T15:18:59.249904+00:00 [queued]>
[2023-11-30T23:19:05.020+0800] {taskinstance.py:1159} INFO - Dependencies all met for dep_context=requeueable deps ti=<TaskInstance: fantasy_premier_league_second_debug.get_old_date manual__2023-11-30T15:18:59.249904+00:00 [queued]>
[2023-11-30T23:19:05.020+0800] {taskinstance.py:1361} INFO - Starting attempt 1 of 1
[2023-11-30T23:19:05.043+0800] {taskinstance.py:1382} INFO - Executing <Task(PythonOperator): get_old_date> on 2023-11-30 15:18:59.249904+00:00
[2023-11-30T23:19:05.046+0800] {standard_task_runner.py:57} INFO - Started process 49429 to run task
[2023-11-30T23:19:05.053+0800] {standard_task_runner.py:84} INFO - Running: ['airflow', 'tasks', 'run', 'fantasy_premier_league_second_debug', 'get_old_date', 'manual__2023-11-30T15:18:59.249904+00:00', '--job-id', '83', '--raw', '--subdir', 'DAGS_FOLDER/azfar_second_dag.py', '--cfg-path', '/tmp/tmpsyjdtl34']
[2023-11-30T23:19:05.055+0800] {standard_task_runner.py:85} INFO - Job 83: Subtask get_old_date
[2023-11-30T23:19:05.096+0800] {task_command.py:416} INFO - Running <TaskInstance: fantasy_premier_league_second_debug.get_old_date manual__2023-11-30T15:18:59.249904+00:00 [running]> on host azfartitu.
[2023-11-30T23:19:05.225+0800] {taskinstance.py:1662} INFO - Exporting env vars: AIRFLOW_CTX_DAG_OWNER='airflow' AIRFLOW_CTX_DAG_ID='fantasy_premier_league_second_debug' AIRFLOW_CTX_TASK_ID='get_old_date' AIRFLOW_CTX_EXECUTION_DATE='2023-11-30T15:18:59.249904+00:00' AIRFLOW_CTX_TRY_NUMBER='1' AIRFLOW_CTX_DAG_RUN_ID='manual__2023-11-30T15:18:59.249904+00:00'
[2023-11-30T23:19:05.236+0800] {base.py:73} INFO - Using connection ID 'azure_blob_conn_id' for task execution.
[2023-11-30T23:19:06.663+0800] {taskinstance.py:1937} ERROR - Task failed with exception
Traceback (most recent call last):
  File "/home/azfarmustafa/airflow_tutorial/.venv/lib/python3.10/site-packages/airflow/operators/python.py", line 192, in execute
    return_value = self.execute_callable()
  File "/home/azfarmustafa/airflow_tutorial/.venv/lib/python3.10/site-packages/airflow/operators/python.py", line 209, in execute_callable
    return self.python_callable(*self.op_args, **self.op_kwargs)
  File "/home/azfarmustafa/airflow_tutorial/dags/azfar_second_dag.py", line 46, in get_old_date
    parts = path.spilt('/')
AttributeError: 'str' object has no attribute 'spilt'. Did you mean: 'split'?
[2023-11-30T23:19:06.668+0800] {taskinstance.py:1400} INFO - Marking task as FAILED. dag_id=fantasy_premier_league_second_debug, task_id=get_old_date, execution_date=20231130T151859, start_date=20231130T151905, end_date=20231130T151906
[2023-11-30T23:19:06.685+0800] {standard_task_runner.py:104} ERROR - Failed to execute job 83 for task get_old_date ('str' object has no attribute 'spilt'; 49429)
[2023-11-30T23:19:06.714+0800] {local_task_job_runner.py:228} INFO - Task exited with return code 1
[2023-11-30T23:19:06.733+0800] {taskinstance.py:2778} INFO - 0 downstream tasks scheduled from follow-on schedule check
