[2023-12-04T11:24:42.037+0800] {taskinstance.py:1159} INFO - Dependencies all met for dep_context=non-requeueable deps ti=<TaskInstance: fantasy_premier_league.move_file_into_archive_folder scheduled__2023-12-03T03:14:34.012519+00:00 [queued]>
[2023-12-04T11:24:42.049+0800] {taskinstance.py:1159} INFO - Dependencies all met for dep_context=requeueable deps ti=<TaskInstance: fantasy_premier_league.move_file_into_archive_folder scheduled__2023-12-03T03:14:34.012519+00:00 [queued]>
[2023-12-04T11:24:42.049+0800] {taskinstance.py:1361} INFO - Starting attempt 1 of 1
[2023-12-04T11:24:42.078+0800] {taskinstance.py:1382} INFO - Executing <Task(PythonOperator): move_file_into_archive_folder> on 2023-12-03 03:14:34.012519+00:00
[2023-12-04T11:24:42.082+0800] {standard_task_runner.py:57} INFO - Started process 14663 to run task
[2023-12-04T11:24:42.086+0800] {standard_task_runner.py:84} INFO - Running: ['airflow', 'tasks', 'run', 'fantasy_premier_league', 'move_file_into_archive_folder', 'scheduled__2023-12-03T03:14:34.012519+00:00', '--job-id', '114', '--raw', '--subdir', 'DAGS_FOLDER/fantasy_premier_league_dag.py', '--cfg-path', '/tmp/tmp_24yf_jt']
[2023-12-04T11:24:42.088+0800] {standard_task_runner.py:85} INFO - Job 114: Subtask move_file_into_archive_folder
[2023-12-04T11:24:42.150+0800] {task_command.py:416} INFO - Running <TaskInstance: fantasy_premier_league.move_file_into_archive_folder scheduled__2023-12-03T03:14:34.012519+00:00 [running]> on host azfartitu.
[2023-12-04T11:24:42.303+0800] {taskinstance.py:1662} INFO - Exporting env vars: AIRFLOW_CTX_DAG_OWNER='airflow' AIRFLOW_CTX_DAG_ID='fantasy_premier_league' AIRFLOW_CTX_TASK_ID='move_file_into_archive_folder' AIRFLOW_CTX_EXECUTION_DATE='2023-12-03T03:14:34.012519+00:00' AIRFLOW_CTX_TRY_NUMBER='1' AIRFLOW_CTX_DAG_RUN_ID='scheduled__2023-12-03T03:14:34.012519+00:00'
[2023-12-04T11:24:42.318+0800] {logging_mixin.py:154} INFO - 04122023
[2023-12-04T11:24:42.328+0800] {base.py:73} INFO - Using connection ID 'azure_blob_conn_id' for task execution.
[2023-12-04T11:24:43.436+0800] {base.py:73} INFO - Using connection ID 'azure_blob_conn_id' for task execution.
[2023-12-04T11:24:44.329+0800] {taskinstance.py:1937} ERROR - Task failed with exception
Traceback (most recent call last):
  File "/home/azfarmustafa/airflow_tutorial/.venv/lib/python3.10/site-packages/airflow/operators/python.py", line 192, in execute
    return_value = self.execute_callable()
  File "/home/azfarmustafa/airflow_tutorial/.venv/lib/python3.10/site-packages/airflow/operators/python.py", line 209, in execute_callable
    return self.python_callable(*self.op_args, **self.op_kwargs)
  File "/home/azfarmustafa/airflow_tutorial/dags/fantasy_premier_league_dag.py", line 196, in move_file_into_archive_folder
    az_hook.get_file(file_path=temp_file_path, container_name='bronze', blob_name=blob_path)
  File "/home/azfarmustafa/airflow_tutorial/.venv/lib/python3.10/site-packages/airflow/providers/microsoft/azure/hooks/wasb.py", line 391, in get_file
    stream = self.download(container_name=container_name, blob_name=blob_name, **kwargs)
  File "/home/azfarmustafa/airflow_tutorial/.venv/lib/python3.10/site-packages/airflow/providers/microsoft/azure/hooks/wasb.py", line 446, in download
    return blob_client.download_blob(offset=offset, length=length, **kwargs)
  File "/home/azfarmustafa/airflow_tutorial/.venv/lib/python3.10/site-packages/azure/core/tracing/decorator.py", line 78, in wrapper_use_tracer
    return func(*args, **kwargs)
  File "/home/azfarmustafa/airflow_tutorial/.venv/lib/python3.10/site-packages/azure/storage/blob/_blob_client.py", line 942, in download_blob
    return StorageStreamDownloader(**options)
  File "/home/azfarmustafa/airflow_tutorial/.venv/lib/python3.10/site-packages/azure/storage/blob/_download.py", line 366, in __init__
    self._response = self._initial_request()
  File "/home/azfarmustafa/airflow_tutorial/.venv/lib/python3.10/site-packages/azure/storage/blob/_download.py", line 462, in _initial_request
    process_storage_error(error)
  File "/home/azfarmustafa/airflow_tutorial/.venv/lib/python3.10/site-packages/azure/storage/blob/_shared/response_handlers.py", line 184, in process_storage_error
    exec("raise error from None")   # pylint: disable=exec-used # nosec
  File "<string>", line 1, in <module>
  File "/home/azfarmustafa/airflow_tutorial/.venv/lib/python3.10/site-packages/azure/storage/blob/_download.py", line 414, in _initial_request
    location_mode, response = self._clients.blob.download(
  File "/home/azfarmustafa/airflow_tutorial/.venv/lib/python3.10/site-packages/azure/core/tracing/decorator.py", line 78, in wrapper_use_tracer
    return func(*args, **kwargs)
  File "/home/azfarmustafa/airflow_tutorial/.venv/lib/python3.10/site-packages/azure/storage/blob/_generated/operations/_blob_operations.py", line 1611, in download
    map_error(status_code=response.status_code, response=response, error_map=error_map)
  File "/home/azfarmustafa/airflow_tutorial/.venv/lib/python3.10/site-packages/azure/core/exceptions.py", line 165, in map_error
    raise error
azure.core.exceptions.ResourceNotFoundError: The specified blob does not exist.
RequestId:edca4225-801e-0026-3a61-265ad3000000
Time:2023-12-04T03:24:30.3223066Z
ErrorCode:BlobNotFound
Content: <?xml version="1.0" encoding="utf-8"?><Error><Code>BlobNotFound</Code><Message>The specified blob does not exist.
RequestId:edca4225-801e-0026-3a61-265ad3000000
Time:2023-12-04T03:24:30.3223066Z</Message></Error>
[2023-12-04T11:24:44.359+0800] {taskinstance.py:1400} INFO - Marking task as FAILED. dag_id=fantasy_premier_league, task_id=move_file_into_archive_folder, execution_date=20231203T031434, start_date=20231204T032442, end_date=20231204T032444
[2023-12-04T11:24:44.386+0800] {standard_task_runner.py:104} ERROR - Failed to execute job 114 for task move_file_into_archive_folder (The specified blob does not exist.
RequestId:edca4225-801e-0026-3a61-265ad3000000
Time:2023-12-04T03:24:30.3223066Z
ErrorCode:BlobNotFound
Content: <?xml version="1.0" encoding="utf-8"?><Error><Code>BlobNotFound</Code><Message>The specified blob does not exist.
RequestId:edca4225-801e-0026-3a61-265ad3000000
Time:2023-12-04T03:24:30.3223066Z</Message></Error>; 14663)
[2023-12-04T11:24:44.431+0800] {local_task_job_runner.py:228} INFO - Task exited with return code 1
[2023-12-04T11:24:44.482+0800] {taskinstance.py:2778} INFO - 0 downstream tasks scheduled from follow-on schedule check
