[2023-11-30T16:01:53.472+0800] {taskinstance.py:1159} INFO - Dependencies all met for dep_context=non-requeueable deps ti=<TaskInstance: fantasy_premier_league_second_debug.get_list_folder scheduled__2023-11-29T08:01:49.190570+00:00 [queued]>
[2023-11-30T16:01:53.478+0800] {taskinstance.py:1159} INFO - Dependencies all met for dep_context=requeueable deps ti=<TaskInstance: fantasy_premier_league_second_debug.get_list_folder scheduled__2023-11-29T08:01:49.190570+00:00 [queued]>
[2023-11-30T16:01:53.479+0800] {taskinstance.py:1361} INFO - Starting attempt 1 of 1
[2023-11-30T16:01:53.499+0800] {taskinstance.py:1382} INFO - Executing <Task(PythonOperator): get_list_folder> on 2023-11-29 08:01:49.190570+00:00
[2023-11-30T16:01:53.502+0800] {standard_task_runner.py:57} INFO - Started process 38349 to run task
[2023-11-30T16:01:53.507+0800] {standard_task_runner.py:84} INFO - Running: ['airflow', 'tasks', 'run', 'fantasy_premier_league_second_debug', 'get_list_folder', 'scheduled__2023-11-29T08:01:49.190570+00:00', '--job-id', '71', '--raw', '--subdir', 'DAGS_FOLDER/azfar_second_dag.py', '--cfg-path', '/tmp/tmprk3kmjpc']
[2023-11-30T16:01:53.508+0800] {standard_task_runner.py:85} INFO - Job 71: Subtask get_list_folder
[2023-11-30T16:01:53.548+0800] {task_command.py:416} INFO - Running <TaskInstance: fantasy_premier_league_second_debug.get_list_folder scheduled__2023-11-29T08:01:49.190570+00:00 [running]> on host azfartitu.
[2023-11-30T16:01:53.612+0800] {taskinstance.py:1662} INFO - Exporting env vars: AIRFLOW_CTX_DAG_OWNER='airflow' AIRFLOW_CTX_DAG_ID='fantasy_premier_league_second_debug' AIRFLOW_CTX_TASK_ID='get_list_folder' AIRFLOW_CTX_EXECUTION_DATE='2023-11-29T08:01:49.190570+00:00' AIRFLOW_CTX_TRY_NUMBER='1' AIRFLOW_CTX_DAG_RUN_ID='scheduled__2023-11-29T08:01:49.190570+00:00'
[2023-11-30T16:01:53.612+0800] {taskinstance.py:1937} ERROR - Task failed with exception
Traceback (most recent call last):
  File "/home/azfarmustafa/airflow_tutorial/.venv/lib/python3.10/site-packages/airflow/operators/python.py", line 192, in execute
    return_value = self.execute_callable()
  File "/home/azfarmustafa/airflow_tutorial/.venv/lib/python3.10/site-packages/airflow/operators/python.py", line 209, in execute_callable
    return self.python_callable(*self.op_args, **self.op_kwargs)
  File "/home/azfarmustafa/airflow_tutorial/dags/azfar_second_dag.py", line 40, in get_list_folder
    list_of_files = az_hook.get_blobs_list(container_name=container_name)
AttributeError: 'AzureDataLakeStorageV2Hook' object has no attribute 'get_blobs_list'
[2023-11-30T16:01:53.620+0800] {taskinstance.py:1400} INFO - Marking task as FAILED. dag_id=fantasy_premier_league_second_debug, task_id=get_list_folder, execution_date=20231129T080149, start_date=20231130T080153, end_date=20231130T080153
[2023-11-30T16:01:53.641+0800] {standard_task_runner.py:104} ERROR - Failed to execute job 71 for task get_list_folder ('AzureDataLakeStorageV2Hook' object has no attribute 'get_blobs_list'; 38349)
[2023-11-30T16:01:53.679+0800] {local_task_job_runner.py:228} INFO - Task exited with return code 1
[2023-11-30T16:01:53.692+0800] {taskinstance.py:2778} INFO - 0 downstream tasks scheduled from follow-on schedule check
