[2023-11-30T23:20:29.843+0800] {taskinstance.py:1159} INFO - Dependencies all met for dep_context=non-requeueable deps ti=<TaskInstance: fantasy_premier_league_second_debug.get_old_date manual__2023-11-30T15:20:26.427609+00:00 [queued]>
[2023-11-30T23:20:29.849+0800] {taskinstance.py:1159} INFO - Dependencies all met for dep_context=requeueable deps ti=<TaskInstance: fantasy_premier_league_second_debug.get_old_date manual__2023-11-30T15:20:26.427609+00:00 [queued]>
[2023-11-30T23:20:29.850+0800] {taskinstance.py:1361} INFO - Starting attempt 1 of 1
[2023-11-30T23:20:29.868+0800] {taskinstance.py:1382} INFO - Executing <Task(PythonOperator): get_old_date> on 2023-11-30 15:20:26.427609+00:00
[2023-11-30T23:20:29.873+0800] {standard_task_runner.py:57} INFO - Started process 49558 to run task
[2023-11-30T23:20:29.877+0800] {standard_task_runner.py:84} INFO - Running: ['airflow', 'tasks', 'run', 'fantasy_premier_league_second_debug', 'get_old_date', 'manual__2023-11-30T15:20:26.427609+00:00', '--job-id', '85', '--raw', '--subdir', 'DAGS_FOLDER/azfar_second_dag.py', '--cfg-path', '/tmp/tmpnvogj2ks']
[2023-11-30T23:20:29.879+0800] {standard_task_runner.py:85} INFO - Job 85: Subtask get_old_date
[2023-11-30T23:20:29.918+0800] {task_command.py:416} INFO - Running <TaskInstance: fantasy_premier_league_second_debug.get_old_date manual__2023-11-30T15:20:26.427609+00:00 [running]> on host azfartitu.
[2023-11-30T23:20:30.019+0800] {taskinstance.py:1662} INFO - Exporting env vars: AIRFLOW_CTX_DAG_OWNER='airflow' AIRFLOW_CTX_DAG_ID='fantasy_premier_league_second_debug' AIRFLOW_CTX_TASK_ID='get_old_date' AIRFLOW_CTX_EXECUTION_DATE='2023-11-30T15:20:26.427609+00:00' AIRFLOW_CTX_TRY_NUMBER='1' AIRFLOW_CTX_DAG_RUN_ID='manual__2023-11-30T15:20:26.427609+00:00'
[2023-11-30T23:20:30.041+0800] {base.py:73} INFO - Using connection ID 'azure_blob_conn_id' for task execution.
[2023-11-30T23:20:31.398+0800] {taskinstance.py:1937} ERROR - Task failed with exception
Traceback (most recent call last):
  File "/home/azfarmustafa/airflow_tutorial/.venv/lib/python3.10/site-packages/airflow/operators/python.py", line 192, in execute
    return_value = self.execute_callable()
  File "/home/azfarmustafa/airflow_tutorial/.venv/lib/python3.10/site-packages/airflow/operators/python.py", line 209, in execute_callable
    return self.python_callable(*self.op_args, **self.op_kwargs)
  File "/home/azfarmustafa/airflow_tutorial/dags/azfar_second_dag.py", line 50, in get_old_date
    non_recent_date = [date for date, count in date_count.items() if count > 1 and date != max(date_counts, key=int)]
NameError: name 'date_count' is not defined. Did you mean: 'date_counts'?
[2023-11-30T23:20:31.405+0800] {taskinstance.py:1400} INFO - Marking task as FAILED. dag_id=fantasy_premier_league_second_debug, task_id=get_old_date, execution_date=20231130T152026, start_date=20231130T152029, end_date=20231130T152031
[2023-11-30T23:20:31.426+0800] {standard_task_runner.py:104} ERROR - Failed to execute job 85 for task get_old_date (name 'date_count' is not defined; 49558)
[2023-11-30T23:20:31.456+0800] {local_task_job_runner.py:228} INFO - Task exited with return code 1
[2023-11-30T23:20:31.477+0800] {taskinstance.py:2778} INFO - 0 downstream tasks scheduled from follow-on schedule check
